<?xml version="1.0"?>
<robot name="my_robot">
  <material name="gray">
    <color rgba="0.5 0.5 0.5 1.0"/>
  </material>
  <link name="base_link">
    <visual>
      <geometry>
        <mesh filename="package://my_robot_description/models/Oberteil.stl"/>
      </geometry>
      <origin xyz="0 -0.025 0" rpy="0 0 0"/>
      <material name="gray"/>
    </visual>
  </link>

  <link name="base_wheel_left">
    <visual>
      <geometry>
        <mesh filename="package://my_robot_description/models/Rad_links.stl"/>
      </geometry>
      <origin xyz="0 0 0" rpy="0 0 0"/>
      <material name="gray"/>
    </visual>
  </link>

  <link name="base_wheel_right">
    <visual>
      <geometry>
        <mesh filename="package://my_robot_description/models/Rad_rechts.stl"/>
      </geometry>
      <origin xyz="0 0 0" rpy="0 0 0"/>
      <material name="gray"/>
    </visual>
  </link>

  <link name="base_lidar">
    <visual>
      <geometry>
        <mesh filename="package://my_robot_description/models/Lidar.stl"/>
      </geometry>
      <origin xyz="0 0 0" rpy="0 0 0"/>
      <material name="gray"/>
    </visual>
  </link>

  <link name="small_base">
    <visual>
      <geometry>
        <mesh filename="package://my_robot_description/models/Unterteil.stl"/>
      </geometry>
      <origin xyz="0 0 0" rpy="0 0 0"/>
      <material name="gray"/>
    </visual>
  </link>

  <link name="small_base_wheel_front">
    <visual>
      <geometry>
        <mesh filename="package://my_robot_description/models/Rad_vorne.stl"/>
      </geometry>
      <origin xyz="0 0 0" rpy="0 0 0"/>
      <material name="gray"/>
    </visual>
  </link>

  <link name="small_base_brush_left">
    <visual>
      <geometry>
        <mesh filename="package://my_robot_description/models/Buerste_links.stl"/>
      </geometry>
      <origin xyz="0 0 0" rpy="0 0 0"/>
      <material name="gray"/>
    </visual>
  </link>

  <link name="small_base_brush_right">
    <visual>
      <geometry>
        <mesh filename="package://my_robot_description/models/Buerste_rechts.stl"/>
      </geometry>
      <origin xyz="0 0 0" rpy="0 0 0"/>
      <material name="gray"/>
    </visual>
  </link>

  <joint name="wheel_left_to_base" type="continuous">
    <parent link="base_link"/>
    <child link="base_wheel_left"/>
    <origin xyz="-1.59 0.65 0.26" rpy="0 0 0"/>
    <axis xyz="0 1 0"/>
  </joint>

  <joint name="wheel_right_to_base" type="continuous">
    <parent link="base_link"/>
    <child link="base_wheel_right"/>
    <origin xyz="-1.59 -0.65 0.26" rpy="0 0 0"/>
    <axis xyz="0 1 0"/>
  </joint>

  <joint name="lidar_to_base" type="fixed">
    <parent link="base_link"/>
    <child link="base_lidar"/>
    <origin xyz="-0.77 0 3.05" rpy="0 0 0"/>
    <axis xyz="1 0 0"/> 
  </joint>

  <joint name="small_base_to_base" type="continuous">
    <parent link="base_link"/>
    <child link="small_base"/>
    <origin xyz="0.15 0 1.3" rpy="0 0 0"/>
    <axis xyz="1 0 0"/> 
  </joint>

  <joint name="wheel_front_to_small_base" type="continuous">
    <parent link="small_base"/>
    <child link="small_base_wheel_front"/>
    <origin xyz="-0.12 0 -1.04" rpy="0 0 0"/>
    <axis xyz="0 1 0"/> 
  </joint>

  <joint name="brush_left_to_small_base" type="continuous">
    <parent link="small_base"/>
    <child link="small_base_brush_left"/>
    <origin xyz="1.05 0.55 -0.925" rpy="0 0 0"/>
    <axis xyz="1 0 0"/> 
  </joint>

  <joint name="brush_right_to_small_base" type="continuous">
    <parent link="small_base"/>
    <child link="small_base_brush_right"/>
    <origin xyz="1.05 -0.55 -0.925" rpy="0 0 0"/>
    <axis xyz="1 0 0"/> 
  </joint>
</robot>
